Workbook

Sheet 1、邮件流程目录
A1: 运营邮件流程
A2: 1.通用邮件中寻找是否有合适的邮件可以复用
A3: 2.若无通用模板可以使用，选择合适的结尾，本地化回来之后使用邮件生成表生成完整邮件发送即可
A4: 通用邮件目录
A5: 版本更新 | B5: 更新后补偿 | C5: 账号封禁 | D5: 不正当游戏封号 | E5: 开服合服 | F5: 开新服
B6: 延迟更新公告 | D6: 非法获得宝石道具封号 | F6: 合服公告
D7: 发布广告封号 | F7: 合服补偿
A8: 服务器维护 | B8: 临时维护 | D8: 恶意获利封号
B9: 维护超时 | D9: 恶意刷资源被处理
D10: 恶意增加战力被处理 | E10: 更新调整 | F10: 英雄平衡性调整补偿
A11: 问卷调查 | B11: 问卷发放 | D11: 举报类BUG（利用游戏漏洞获利）奖励 | F11: 数值平衡性调整补偿
B12: 问卷调查奖励 | D12: 体验类BUG（影响玩家体验）奖励 | F12: 平衡性调整说明
D13: 全服表扬
A14: 故障问题 | B14: 问题已解决 | E14: 活动相关 更新至2021.8.13 | F14: 决战卫星之巅开启
B15: 数据异常 | F15: 狂飙拉力赛任务无法完成问题已解决
B16: 游戏卡顿 | F16: 怒气值异常问题修复
B17: 部队丢失 | F17: 决战卫星之巅奖励丢失
B18: 部队丢失修复 | F18: 决战卫星之巅时间调整
B19: 活动排名异常修复 | F19: 地图改动补偿
B20: 邮件回档 | F20: 新版本问题已修复
B21: 奖励补发 | F21: 活动异常下线
E23: 问卷公告

Sheet 2、通用邮件模板
A1: 文本显色规则： 绿色：邮件里带跳转功能的超链接 黄色：除超链接以外的重点信息，例如 将在10分钟后维护，本次更新将重置您的主城位置
A2: 使用场景 | C2: cn | D2: en-loc | E2: fr | F2: de | G2: po | H2: zh | I2: id | J2: th | K2: sp | L2: ru | M2: tr | N2: vi | O2: it | P2: pl
A3: 版本更新 | B3: 更新后补偿 | C3: 版本更新礼物 | D3: Version Update Reward | E3: Récompense pour la mise à jour | F3: Versions-Update-Belohnung | G3: Recompensa de Atualização | H3: 版本更新禮物 | I3: Hadiah Pembaruan Versi | J3: รางวัลการอัปเดตเวอร์ชัน | K3: Recompensa por actualización de versión | L3: Награда за обновление версии | M3: Sürüm Güncelleme Ödülü | N3: Phần thưởng cập nhật phiên bản
C4: 亲爱的指挥官：\n\n感谢您的更新，在此我们送上一份更新礼物，祝您玩得开心！\n\n我们会继续关注大家的反馈和建议，通过持续优化提升游戏品质，给您带来更好的游戏体验。\n\n欢迎大家通过Discord官方社区或游戏内客服服务和我们积极沟通。\n[-1#Official Discord](herf=https://discord.gg/RncnPNw)\n\n罗杰副官 | D4: Dear Captain,\n\nThanks for updating! We've included a small update reward for you. Happy gaming!\n\nWe will continue to listen to your feedback and keep optimizing to bring you a better gaming experience.\n\nPlease don't hesitate to get in touch with us via Discord or the in-game customer support. [-1#Official Discord](herf=https://discord.gg/RncnPNw)\n\nDeputy Roger | F4: Lieber Captain,\n\nvielen Dank, dass du das Update durchgeführt hast! Wir haben eine kleine Update-Belohnung für dich beigefügt. Viel Spaß beim Spielen!\n\nWir werden auch in Zukunft auf dein Feedback hören und das Spiel weiter optimieren, um dir ein noch besseres Spielerlebnis zu bieten.\n\nBitte zögere nicht, mit uns über Discord oder den Ingame-Kundensupport in Kontakt zu treten. [-1#Offizieller Discord](herf=https://discord.gg/RncnPNw)\n\nAdjudant Roger | G4: Caro Capitão,\n\nAgradecemos por fazer a atualização! Incluímos uma pequena recompensa de atualização para você. Bons jogos!\n\nContinuaremos a ouvir seu feedback, mantendo assim a experiência de jogo otimizada.\n\nNão deixe de entrar em contato conosco no Discord ou no suporte ao cliente dentro do jogo. [-1#Discord Oficial](herf=https://discord.gg/RncnPNw)\n\nDelegado Roger | H4: 親愛的指揮官：\n\n感謝您的更新，在此我們送上一份更新禮物，祝您玩得開心！\n\n我們會繼續關注大家的反饋和建議，通過持續優化提升遊戲品質，給您帶來更好的遊戲體驗。\n\n歡迎大家通過Discord官方社區或遊戲內客服服務和我們積極溝通。\n[-1#Official Discord](herf=https://discord.gg/RncnPNw)\n\n羅傑副官 | I4: Kapten yang terhormat,\n\nTerima kasih telah melakukan pembaruan! Kami telah menyertakan hadiah pembaruan kecil untukmu. Selamat bermain game!\n\nKami akan terus mendengarkan umpan balikmu dan terus mengoptimalkan untuk memberikan pengalaman bermain game yang lebih baik.\n\nJangan ragu untuk menghubungi kami melalui Discord atau dukungan pelanggan dalam game. [-1#Official Discord](herf=https://discord.gg/RncnPNw)\n\nDeputi Roger | J4: ถึงท่านผู้บัญชาการ\n\nขอบคุณสำหรับการอัปเดต! เราเลยขอมอบของรางวัลการอัปเดตชิ้นเล็ก ๆ นี้ให้ ขอให้มีความสุขในการเล่นเกมนะ!\n\nเราพร้อมรับฟังความคิดเห็นของนายและปรับปรุงอย่างต่อเนื่องเพื่อนำเสนอประสบการณ์การเล่นเกมที่ดียิ่ง ๆ ขึ้นไป\n\nโปรดอย่าลังเลที่จะติดต่อเราผ่านทาง Discord หรือฝ่ายสนับสนุนลูกค้าในเกม [-1#Official Discord](herf=https://discord.gg/RncnPNw)\n\nท่านรองโรเจอร์ | K4: Querido Capitán,\n\n¡Gracias por actualizar! ¡Hemos incluido una pequeña recompensa por actualización para ti! Felices juegos. \n\nContinuaremos escuchando tus comentarios y nos mantendremos optimizando para traerte una mejor experiencia de juego.\n\nPor favor, no dudes en ponerte en contacto con nosotros mediante Discord o a través del soporte al cliente del juego. [-1#Discord Oficial](herf=https://discord.gg/RncnPNw)\n\nComisario Roger | L4: Уважаемый капитан!\n\nСпасибо, что обновляете игру! Мы отправляем вам небольшую награду за обновление. Счастливой игры!\n\nМы продолжим изучать ваши отзывы и оптимизировать качество игры, чтобы оставить у вас наилучшие впечатления.\n\nВы в любой момент можете написать нам в Discord или в игровую службу поддержки. [-1#Сервер Discord](herf=https://discord.gg/RncnPNw)\n\nПомощник Роджер | M4: Sevgili Kaptan,\n\nGüncellediğin için teşekkürler! Senin için küçük bir güncelleme ödülümüz var. Mutlu oyunlar!\n\nGeri bildirimlerini dinlemeye ve sana daha iyi bir deneyim sunmak adına optimize etmeye devam edeceğiz.\n\nDiscord üzerinden veya oyun içi müşteri desteğinden bize ulaşabilirsin. [-1#Resmî Discord](herf=https://discord.gg/RncnPNw)\n\nYardımcı Roger | N4: Thưa Thủ Lĩnh,\n\nCảm ơn các bạn đã cập nhật! Chúng tôi đã đính kèm một phần thưởng cập nhật nhỏ dành cho bạn. Chúc bạn chơi game vui vẻ!\n\nChúng tôi sẽ tiếp tục lắng nghe phản hồi của bạn để tiếp tục tối ưu hóa và mang lại cho bạn trải nghiệm chơi game tốt hơn.\n\nVui lòng liên hệ với chúng tôi qua Discord hoặc bộ phận hỗ trợ khách hàng trong trò chơi. [-1#Discord chính thức](herf=https://discord.gg/RncnPNw)\n\nPhụ tá Roger
B5: 延迟更新公告 | C5: 0.22.0版本更新延迟公告 | D5: Version 0.22.0 Update Delay | E5: Retard de mise à jour 0.22.0 | F5: Version 0.22.0 Update-Verzögerung | G5: Adiamento da atualização 0.22.0 | H5: 0.22.0版本更新延遲公告 | I5: Penundaan Pembaruan Versi 0.22.0 | J5: ความล่าช้าในการอัปเดตเวอร์ชัน 0.22.0 | K5: Retraso en la actualización a la versión 0.22.0 | L5: Задержка обновления до версии 0.22.0 | M5: Sürüm 0.22.0 Güncelleme Ertelemesi | N5: Trì hoãn Cập nhật phiên bản 0.22.0
C6: 亲爱的指挥官：\n\n0.22.0版本更新时间将会被<color=#ffa200>延迟</color>，具体时间我们将另行通知。\n\n感谢您对Age of Apes的理解与支持，祝愿火箭发射顺利！\n\n罗杰副官 | D6: Dear Captain,\n\nThe version 0.22.0 update has been <color=#ffa200>delayed</color>. We will notify you as soon as the new update time is confirmed.\n\nThank you for your understanding and support. See you around the Tavern!\n\nDeputy Roger | E6: Cher capitaine,\n\nLa mise à jour 0.22.0 a pris du <color=#ffa200>retard</color>. Nous vous tiendrons informé dès que l'horaire de fin des opérations sera confirmé.\n\nMerci pour votre compréhension et votre soutien. A bientôt à la taverne!\n\nRoger l'assistant | F6: Lieber Captain,\n\nDas Update auf die Version 0.22.0 hat sich <color=#ffa200>verzögert</color. Wir werden dich benachrichtigen, sobald der neue Update-Zeitpunkt bestätigt ist.\n\nVielen Dank für dein Verständnis und deine Unterstützung. Wir sehen uns in der Taverne!\n\nAdjudant Roger | G6: Caro Capitão,\n\nA atualização para a versão 0.22.0 foi <color=#ffa200>adiada</color. Notificaremos você assim que a nova data de atualização for confirmada.\n\nNossa equipe agradece seu apoio e compreensão. Vemos você na taverna!\n\nDelegado Roger | H6: 親愛的指揮官：\n\n0.22.0版本更新時間將會被<color=#ffa200>延遲</color>，具體時間我們將另行通知。\n\n感謝你對Age of Apes的理解與支持，祝愿火箭發射順利！\n\n羅傑副官 | I6: Kapten yang terhormat,\n\nPembaruan versi 0.22.0 telah <color=#ffa200>ditunda</color. Kami akan memberitahukanmu segera setelah waktu pembaruan terkini dikonfirmasi.\n\nTerima kasih atas pengertian dan dukunganmu. Sampai jumpa di sekitar Kedai!\n\nDeputi Roger | J6: ถึงท่านผู้บัญชาการ\n\nการอัปเดตเวอร์ชัน 0.22.0 <color=#ffa200>เกิดความล่าช้า</color> เราจะแจ้งให้นายทราบทันทีที่มีการยืนยันเวลาอัปเดตใหม่\n\nขอขอบคุณสำหรับความเข้าใจและการสนับสนุนของนาย แล้วไว้เจอกันแถว ๆ โรงแรมนะ!\n\nท่านรองโรเจอร์ | K6: Querido Capitán, \n\nLa actualización a la versión 0.22.0 ha sido <color=#ffa200>retrasada</color. Te notificaremos tan pronto como el horario de la nueva actualización este confirmado. \n\nGracias por tu comprensión y apoyo. ¡Nos vemos en la Taberna!\n\nComisario Roger | L6: Уважаемый капитан!\n\nОбновление до версии 0.22.0 <color=#ffa200>отложено</color>. Как только мы узнаем точное время обновления, мы вам сообщим.\n\nСпасибо за понимание и поддержку. Увидимся в таверне!\n\nПомощник Роджер | M6: Sevgili Kaptan,\n\nSürüm 0.22.0 güncellemesi <color=#ffa200>ertelendi</color. Yeni güncelleme zamanı belli olduğunda seni bilgilendireceğiz.\n\nAnlayışın ve desteğin için teşekkürler. Tavernada görüşürüz!\n\nYardımcı Roger | N6: Thưa Thủ Lĩnh,\n\nBản cập nhật của phiên bản 0.22.0 sẽ <color=#ffa200>bị hoãn lại</color. Chúng tôi sẽ thông báo ngay sau khi xác nhận xong thời gian cập nhật mới.\n\nCảm ơn các bạn đã thông cảm và hỗ trợ. Hẹn gặp lại ở Tửu Quán nhé!\n\nPhụ tá Roger
A7: 服务器维护 | B7: 临时维护 | C7: 临时维护公告 | D7: Server Maintenance Notice | E7: Maintenance des serveurs | F7: Hinweis zur Serverwartung | G7: Aviso de manutenção do servidor | H7: 臨時維護公告 | I7: Pemberitahuan Pemeliharaan Server | J7: ประกาศการบำรุงรักษาเซิร์ฟเวอร์ | K7: Aviso de Mantenimiento de Servidor | L7: Уведомление об обслуживании сервера | M7: Sunucu Bakımı Bildirimi | N7: Thông báo bảo trì máy chủ
C8: 亲爱的指挥官：\n\n为了更好地帮助你领导这座城市，我们将在<color=#ffa200>2021-04-01 00:00 UTC</color>进入维护状态，维护时长大约为<color=#ffa200>30分钟</color>，维护期间你将无法正常进入游戏。\n为您带来不便深感歉意，在此为您送上一份补偿，请注意查收。\n本次维护不排除延迟开启的可能，如若延迟，请关注社区发布的具体开服时间。感谢您对Age of Apes的理解与支持，祝愿火箭发射顺利！\n[-1#Official Discord](herf=https://discord.gg/RncnPNw)\n\n罗杰副官 | D8: Dear Captain,\n\nTo help you better lead your City, we'll be performing server maintenance starting at <color=#ffa200>2021-04-01 00:00 UTC</color>. It'll take approximately <color=#ffa200>30 minutes</color>. You will not be able to access the game during this time.\n\nWe apologize for the inconvenience and have included a small gift for you as compensation.\n\nMaintenance may take longer. If so, please stay tuned for updates posted to our Monkey Community.\n\nThanks for your understanding and support. See you around the Tavern!\n\n[-1#Official Discord](herf=https://discord.gg/RncnPNw)\n\nDeputy Roger | E8: Cher capitaine,\n\nPour vous aider à mieux gérer votre ville, nous prévoyons des opérations de maintenance des serveurs à partir du <color=#ffa200>01/04/2021 à 00:00 (TU)</color>. Elles prendront environ <color=#ffa200>30 minutes</color>. Pendant cette période, vous ne pourrez pas accéder au jeu.\n\nNous vous prions de nous excuser pour ce désagrément et vous offrons un petit cadeau en dédommagement.\n\nIl se peut que les opérations de maintenance prennent plus de temps. Pour en être informé, nous vous invitons à rejoindre notre communauté des singes.\n\nMerci pour votre compréhension et votre soutien. A bientôt à la taverne!\n\n[-1#Discord officiel](herf=https://discord.gg/RncnPNw)\n\nRoger l'assistant | F8: Lieber Captain,\n\nDamit du deine Stadt besser führen kannst, werden wir beginnend um <color=#ffa200>01.04.2021 00:00 UTC</color> eine Serverwartung durchführen. Sie wird etwa <color=#ffa200>30 Minuten</color> dauern. Während dieser Zeit wirst du nicht auf das Spiel zugreifen können.\n\nWir entschuldigen uns für die Unannehmlichkeiten und haben als Entschädigung ein kleines Geschenk für dich beigefügt.\n\nDie Wartungsarbeiten können möglicherweise länger dauern. Wenn dies der Fall ist, halte dich bitte über unsere Affen-Community auf dem Laufenden.\n\nVielen Dank für dein Verständnis und deine Unterstützung. Wir sehen uns in der Taverne!\n\n[-1#Offizieller Discord](herf=https://discord.gg/RncnPNw)\n\nAdjudant Roger | G8: Caro Capitão,\n\nPara ajudar você a melhorar a liderança de sua cidade, vamos fazer uma manutenção de servidor em <color=#ffa200>01/04/2021, às 00:00 (fuso UTC)</color>. Ela demorará cerca de <color=#ffa200>30 minutos</color>. Não será possível acessar o jogo durante este período.\n\nLamentamos pelo inconveniente e, por isso, incluímos um pequeno presente para você como compensação.\n\nA manutenção pode levar mais tempo. Se este for o caso, haverá atualizações sobre isso em nossa Comunidade dos Macacos\n\nNossa equipe agradece seu apoio e compreensão. Vemos você na taverna!\n\n[-1#Discord Oficial](herf=https://discord.gg/RncnPNw)\n\nDelegado Roger | H8: 親愛的指揮官：\n\n為了更好地幫助你領導這座城市，我們將在<color=#ffa200>2021-04-01 00:00 UTC</color>進入維護狀態，維護時長大約為<color=#ffa200>30分鐘< /color>，維護期間你將無法正常進入遊戲。\n為您帶來不便深感歉意，在此為您送上一份補償，請注意查收。\n本次維護不排除延遲開啟的可能，如若延遲，請關注社區發布的具體開服時間。感謝你對Age of Apes的理解與支持，祝愿火箭發射順利！\n[-1#Official Discord](herf=https://discord.gg/RncnPNw)\n\n羅傑副官 | I8: Kapten yang terhormat,\n\nUntuk membantumu memimpin Kota dengan lebih baik, kami akan melakukan pemeliharaan server pada <color=#ffa200>2021-04-01 00:00 UTC</color>. Pemeliharan akan memerlukan waktu sekitar <color=#ffa200>30 menit</color>. Kamu tidak akan bisa mengakses game selama waktu tersebut.\n\nKami mohon maaf atas ketidaknyamanannya dan telah menyertakan hadiah kecil untukmu sebagai kompensasi.\n\nPemeliharaan mungkin memerlukan waktu lebih lama. Jika demikian, nantikan pembaruan yang diposting di Komunitas Kera kami.\n\nTerima kasih atas pengertian dan dukunganmu. Sampai jumpa di sekitar Kedai!\n\n[-1#Official Discord](herf=https://discord.gg/RncnPNw)\n\nDeputi Roger | J8: ถึงท่านผู้บัญชาการ\n\nเพื่อช่วยให้นายบัญชาการเมืองของนายได้ดีขึ้น เราจะดำเนินการบำรุงรักษาเซิร์ฟเวอร์โดยเริ่มตั้งแต่วันที่<color=#ffa200> 01-04-2021 00:00 ตามเวลา UTC</color> โดยจะใช้เวลาประมาณ<color=#ffa200> 30 นาที </color>ซึ่งนายจะไม่สามารถเข้าเกมได้ในช่วงเวลาดังกล่าว\n\nขออภัยในความไม่สะดวก และเราขอมอบของรางวัลเล็ก ๆ น้อย ๆ นี้ให้เป็นการชดเชย\n\nการบำรุงรักษาอาจใช้เวลานานกว่าที่แจ้งไว้ได้ หากเป็นเช่นนั้น โปรดติดตามการอัปเดตที่เราจะโพสต์ไว้ในชุมชนเหล่าลิงของเรา\n\nขอขอบคุณสำหรับความเข้าใจและการสนับสนุนของนาย แล้วไว้เจอกันแถว ๆ โรงแรมนะ!\n\n[-1#Official Discord](herf=https://discord.gg/RncnPNw)\n\nท่านรองโรเจอร์ | K8: Querido Capitán, \n\nPara ayudarte a liderear mejor a tu Ciudad estaremos realizando un mantenimiento del servidor comenzando el día: <color=#ffa200>01-04-2021 00:00 UTC</color>. Tomará aproximadamente <color=#ffa200>30 minutos</color>. No podrás acceder al juego durante este periodo. \n\nNos disculpamos por el inconveniente y hemos incluido un pequeño regalo para ti como compensación. \n\nEl mantenimiento puede durar más tiempo. Si es así, mantente sintonizado para actualizaciones publicadas en nuestra Comunidad Mono. \n\nGracias por tu comprensión y apoyo. ¡Nos vemos en la Taberna!\n\n[-1#Discord Oficial](herf=https://discord.gg/RncnPNw)\n\nComisario Roger | L8: Уважаемый капитан!\n\nЧтобы помочь вам лучше руководить вашим городом, мы проводим техобслуживание начиная с <color=#ffa200>00:00 01.04.2021 (UTC)</color>. Обслуживание займет около <color=#ffa200>30 минут</color>, и в это время вы не сможете войти в игру.\n\nПриносим извинения за неудобства и отправляем вам небольшой подарок в качестве компенсации!\n\nЕсть вероятность, что обслуживание займет больше времени. В этом случае следите за новостями в нашем обезьяньем сообществе.\n\nСпасибо за понимание и поддержку. Увидимся в таверне!\n\n[-1#Официальный Discord](herf=https://discord.gg/RncnPNw)\n\nПомощник Роджер | M8: Sevgili Kaptan,\n\nŞehrine daha iyi liderlik etmeni sağlamak için <color=#ffa200>01.04.2021, 00.00’da (UTC)</color> başlayacak bir sunucu bakımı gerçekleştireceğiz</color>. Yaklaşık <color=#ffa200>30 dakika</color> sürecek. Bu süre içerisinde oyuna erişemeyeceksin.\n\nVerdiğimiz sıkıntıdan ötürü özür dileriz, bunun telafisi olarak sana küçük bir hediye sunuyoruz.\n\nBakım daha uzun sürebilir. Bu durumda, Maymun Topluluğumuzda paylaşılan güncellemeleri lütfen takip et.\n\nAnlayışın ve desteğin için teşekkürler. Tavernada görüşürüz!\n\n[-1#Resmî Discord](herf=https://discord.gg/RncnPNw)\n\nYardımcı Roger | N8: Thưa Thủ Lĩnh,\n\nĐể giúp bạn lãnh đạo Thành phố của mình ngày một tốt hơn, chúng tôi sẽ tiến hành bảo trì máy chủ, bắt đầu từ <color=#ffa200>00:00 ngày 01/04/2021 UTC</color>. Thời gian bảo trì sẽ kéo dài trong khoảng <color=#ffa200>30 phút</color>. Bạn sẽ không thể truy cập vào ứng dụng trong khoảng thời gian này.\n\nChúng tôi xin lỗi vì sự bất tiện này và xin phép được tặng một món quà nhỏ để bù đắp cho bạn.\n\nThời gian bảo trì có thể kéo dài lâu hơn. Nếu việc đó xảy ra, hãy theo dõi các tin tức cập nhật đăng trong Cộng đồng Khỉ của chúng tôi.\n\nCảm ơn bạn đã thông cảm và hỗ trợ. Hẹn gặp lại ở Tửu Quán nhé!\n\n[-1#Discord chính thức](herf=https://discord.gg/RncnPNw)\n\nPhụ tá Roger
B9: 维护超时 | C9: 维护超时说明 | D9: Maintenance Delay | E9: Retard de maintenance | F9: Wartungsverzögerung | G9: Atraso na manutenção | H9: 維護超時說明 | I9: Penundaan Pemeliharaan | J9: ความล่าช้าในการบำรุงรักษา | K9: Retraso del Mantenimiento | L9: Продление техобслуживания | M9: Bakım Ertelemesi | N9: Hoãn bảo trì
C10: 亲爱的指挥官：\n\n你好，由于城市电路发生故障，我们在<color=#ffa200>00:00 UTC</color>开始的系统维护花费了比预估更多的维护时间，现在维护已经结束，你可以正常登录游戏。\n为您带来不便深感歉意，在此为您送上一份补偿，请注意查收。\n\n感谢您对Age of Apes的理解与支持，祝愿火箭发射顺利！\n\n罗杰副官 | D10: Dear Captain,\n\nDue to issues in the city circuits, the maintenance that started at <color=#ffa200>00:00 UTC</color> took longer than expected. Maintenance has now finished and you may log in normally.\n\nWe apologize for the inconvenience and have included a small gift for you as compensation.\n\nThanks for your understanding and support. See you around the Tavern!\n\nDeputy Roger | E10: Cher capitaine,\n\nEn raison d'un dysfonctionnement des circuits de la ville, les opérations de maintenance, qui ont débuté à <color=#ffa200>00:00 (TU)</color>, ont pris plus de temps que prévu. Elles sont à présent achevées et vous pouvez vous connecter normalement.\n\nNous vous prions de nous excuser pour ce désagrément et vous offrons un petit cadeau en dédommagement.\n\nMerci pour votre compréhension et votre soutien. A bientôt à la taverne!\n\nRoger l'assistant | F10: Lieber Captain,\n\nAufgrund von Problemen in den Schaltkreisen der Stadt hat die Wartung, die um <color=#ffa200>00:00 UTC</color> begann, länger gedauert als erwartet. Die Wartungsarbeiten sind nun beendet und du kannst dich normal einloggen.\n\nWir entschuldigen uns für die Unannehmlichkeiten und haben als Entschädigung ein kleines Geschenk für dich beigefügt.\n\nVielen Dank für dein Verständnis und deine Unterstützung. Wir sehen uns in der Taverne!\n\nAdjudant Roger | G10: Caro Capitão,\n\nDevido a problemas nos circuitos da cidade, a manutenção que começou <color=#ffa200>à 00:00 (fuso UTC)</color> levou mais do que o esperado. A manutenção terminou e você pode agora entrar normalmente.\n\nLamentamos pelo inconveniente e, por isso, incluímos um pequeno presente para você como compensação.\n\nNossa equipe agradece seu apoio e compreensão. Vemos você na taverna!\n\nDelegado Roger | H10: 親愛的指揮官：\n\n你好，由於城市電路發生故障，我們在<color=#ffa200>00:00 UTC</color>開始的系統維護花費了比預估更多的維護時間，現在維護已經結束，你可以正常登錄遊戲。\n為您帶來不便深感歉意，在此為您送上一份補償，請注意查收。\n\n感謝你對Age of Apes的理解與支持，祝愿火箭發射順利！\n\n羅傑副官 | I10: Kapten yang terhormat,\n\nKarena masalah di sirkuit kota, perawatan yang dimulai pada <color=#ffa200>00:00 UTC</color> akan memerlukan waktu lebih lama daripada yang diperkirakan. Pemeliharaan telah selesai dan kamu bisa masuk secara normal.\n\nKami mohon maaf atas ketidaknyamanannya dan telah menyertakan hadiah kecil untukmu sebagai kompensasi.\n\nTerima kasih atas pengertian dan dukunganmu. Sampai jumpa di sekitar Kedai!\n\nDeputi Roger | J10: ถึงท่านผู้บัญชาการ\n\nเนื่องจากเกิดปัญหาในวงจรของเมือง การบำรุงรักษาที่เริ่มในเวลา<color=#ffa200> 00:00 UTC</color> จึงใช้เวลานานกว่าที่คาดไว้ ขณะนี้การบำรุงรักษาเสร็จสิ้นแล้ว นายสามารถเข้าสู่ระบบได้ตามปกติ\n\nขออภัยในความไม่สะดวก เราจึงขอมอบของขวัญเล็ก ๆ น้อย ๆ นี้ให้เป็นการชดเชย\n\nขอขอบคุณสำหรับความเข้าใจและการสนับสนุนของนาย แล้วไว้เจอกันแถว ๆ โรงแรมนะ!\n\nท่านรองโรเจอร์ | K10: Querido Capitán, \n\nDebido a problemas con los circuitos de la ciudad, el mantenimiento que había comenzado a las <color=#ffa200>00:00 UTC</color> tomo más tiempo de lo esperado. El mantenimiento ahora ha terminado y ya puedes conectarte normalmente. \n\nNos disculpamos por el inconveniente y hemos incluido un pequeño regalo para ti como compensación.\n\nGracias por tu comprensión y apoyo. ¡Nos vemos en la Taberna!\n\nComisario Roger | L10: Уважаемый капитан!\n\nИз-за проблем в городских сетях техобслуживание, которое началось в <color=#ffa200>00:00 (UTC)</color>, заняло больше времени, чем ожидалось. Сейчас оно закончено, и вы можете войти в игру в обычном режиме.\n\nПриносим извинения за доставленные неудобства и отправляем вам небольшой подарок в качестве компенсации!\n\nСпасибо за понимание и поддержку. Увидимся в таверне!\n\nПомощник Роджер | M10: Sevgili Kaptan,\n\nŞehir devrelerindeki sorunlar yüzünden <color=#ffa200>00.00’da (UTC)</color> başlayan bakım beklenenden uzun sürdü. Bakım şimdi tamamlandı, normal şekilde giriş yapabilirsin.\n\nVerdiğimiz sıkıntıdan ötürü özür dileriz, bunun telafisi olarak sana küçük bir hediye sunuyoruz.\n\nAnlayışın ve desteğin için teşekkürler. Tavernada görüşürüz!\n\nYardımcı Roger | N10: Thưa Thủ Lĩnh,\n\nDo các vấn đề về mạch điện trong thành phố, thời gian bảo trì bắt đầu lúc <color=#ffa200>00:00 UTC</color> đã kéo dài hơn dự kiến. Quá trình bảo trì hiện đã kết thúc và bạn có thể đăng nhập bình thường.\n\nChúng tôi xin lỗi vì sự bất tiện này và xin phép được tặng một món quà nhỏ để bù đắp cho bạn.\n\nCảm ơn bạn đã thông cảm và hỗ trợ. Hẹn gặp lại ở Tửu Quán nhé!\n\nPhụ tá Roger
A11: 问卷调查 | B11: 问卷发放 | C11: 问卷调查 | D11: Survey | E11: Enquête | F11: Umfrage | G11: Pesquisa | H11: 問卷調查 | I11: Survei | J11: แบบสำรวจ | K11: Encuesta | L11: Опрос | M11: Anket | N11: Khảo sát | O11: Sondaggio | P11: Ankieta | Q11: استبيان
C12: 亲爱的指挥官：\n\n恭喜您被选为幸运猴子，来参与我们的问卷调研！为了给您提供更好的游戏体验，您的建议非常重要。在问卷填写完毕后，您将会获得一份很棒的奖励！\n详细规则\n1. 在<color=#ffa200>2021-01-21 00:00 UTC</color>之前完成问卷，您将获得<color=#ffa200>200CD</color>奖励；\n2. 奖励将会在<color=#ffa200>2021-1-27 00:00 UTC</color>之前发放；\n3. 每位玩家只能获得一次奖励；\n4. 您填写的内容我们仅供内部分析使用；\n[-1#问卷](herf=http://questionnaire.tap4fun.com/jq/104274483.aspx?sojumpparm=%7Buser_id%7D)\n\n罗杰副官 | D12: Dear Captain,\n\nCongratulations! You have been selected as one of the lucky monkeys to participate in our survey! In order to provide you with a better gaming experience, we would like to know your suggestions about the game. After completing the survey, you will receive a great reward!\n\nParticipation Rules:\n\n1. Complete the survey before <color=#ffa200>2021-01-21 00:00 UTC</color> to receive <color=#ffa200>200 CDs</color>.\n2. The reward will be issued before <color=#ffa200>2021-1-27 00:00 UTC</color>.\n3. Each player can only get the reward once.\n4. Your survey answers are for internal analysis only.\n\n[-1#Survey](herf=https://www.surveymonkey.com/r/TNW9665?user_id=%7Buser_id%7D)\n\nDeputy Roger | E12: Cher capitaine,\n\nFélicitations! Vous faites partie des rares chanceux sélectionnés pour participer à notre enquête! Afin de vous proposer une expérience de jeu optimale, nous aimerions connaître vos suggestions. Après avoir rempli le questionnaire, vous recevrez une belle récompense!\n\nRèglement:\n\n1. Répondez à l'enquête avant le <color=#ffa200>21/01/2021 à 00:00 (TU)</color> pour recevoir <color=#ffa200>200 CD</color>.\n2. La récompense sera transmise avant le <color=#ffa200>27/01/2021 à 00:00 (TU)</color>.\n3. Une seule récompense par joueur.\n4. Vos réponses à l'enquête seront utilisées pour analyse en interne uniquement.\n\n[-1#Enquête](herf=https://www.surveymonkey.com/r/TNW9665?user_id=%7Buser_id%7D)\n\nRoger l'assistant | F12: Lieber Captain,\n\nHerzlichen Glückwunsch! Du wurdest als einer der glücklichen Affen ausgewählt, die an unserer Umfrage teilnehmen dürfen! Um dir ein besseres Spielerlebnis bieten zu können, möchten wir gerne deine Vorschläge zum Spiel hören. Nach Beendigung der Umfrage erhältst du eine tolle Belohnung!\n\nTeilnahmeregeln:\n\n1. Schließe die Umfrage vor dem <color=#ffa200>21.01.21 00:00 UTC</color> ab, um <color=#ffa200>200 CDs</color> zu erhalten.\n2. Die Belohnung wird vor dem <color=#ffa200>27.01.2021 00:00 Uhr UTC</color> ausgegeben.\n3. Jeder Spieler kann die Belohnung nur einmal erhalten.\n4. Deine Antworten auf die Umfrage sind nur für die interne Auswertung bestimmt.\n\n[-1#Umfrage](herf=https://www.surveymonkey.com/r/TNW9665?user_id=%7Buser_id%7D)\n\nAdjudant Roger | G12: Caro Capitão,\n\nParabéns! Você foi um dos macacos sortudos escolhidos para participar de nossa pesquisa! Para fornecer uma experiência de jogo melhor para você, gostaríamos de ouvir sua opinião sobre o jogo. Ao completar a pesquisa, você receberá uma grande recompensa!\n\nRegras para participar:\n\n1. Conclua a pesquisa antes de <color=#ffa200>21/01/2021, à 00:00 (UTC)</color> para receber <color=#ffa200>200 CDs</color>.\n2. A recompensa será enviada antes de <color=#ffa200>27/01/2021, à 00:00 (UTC)</color>.\n3. Cada jogador só pode conseguir a recompensa uma vez.\n4. Suas respostas serão usadas somente para análise interna de nossa equipe.\n\n[-1#Pesquisa](herf=https://www.surveymonkey.com/r/TNW9665?user_id=%7Buser_id%7D)\n\nDelegado Roger | H12: 親愛的指揮官：\n\n恭喜您被選為幸運猴子，來參與我們的問卷調研！為了給您提供更好的遊戲體驗，您的建議非常重要。在問卷填寫完畢後，您將會獲得一份很棒的獎勵！\n詳細規則\n1. 在<color=#ffa200>2021-01-21 00:00 UTC</color>之前完成問卷，您將獲得<color=#ffa200>200CD</color>獎勵；\n2. 獎勵將會在<color=#ffa200>2021-1-27 00:00 UTC</color>之前發放；\n3. 每位玩家只能獲得一次獎勵；\n4. 您填寫的內容我們僅供內部分析使用；\n[-1#問卷](herf=http://questionnaire.tap4fun.com/jq/104274483.aspx?sojumpparm=%7Buser_id%7D)\n\n羅傑副官 | I12: Kapten yang terhormat,\n\nSelamat! Kamu terpilih sebagai salah satu kera yang beruntung untuk berpartisipasi dalam survei kami! Untuk memberimu pengalaman bermain game yang lebih baik, kami ingin mengetahui saranmu tentang game. Setelah menyelesaikan survei, kamu akan menerima hadiah besar!\n\nAturan Partisipasi:\n\n1. Selesaikan survei sebelum <color=#ffa200>2021-01-21 00:00 UTC</color> untuk menerima <color=#ffa200>200 CD</color>.\n2. Hadiah akan diberikan sebelum <color=#ffa200>2021-1-27 00:00 UTC</color>.\n3. Setiap pemain hanya bisa mendapatkan hadiahnya sekali.\n4. Jawaban surveimu hanya untuk analisis internal.\n\n[-1#Survey](herf=https://www.surveymonkey.com/r/TNW9665?user_id=%7Buser_id%7D)\n\nDeputi Roger | J12: ถึงท่านผู้บัญชาการ\n\nยินดีด้วย! นายได้รับเลือกให้เป็นหนึ่งในลิงผู้โชคดีจากการเข้าร่วมแบบสำรวจของเรา! เพื่อให้นายได้รับประสบการณ์การเล่นเกมที่ดีขึ้น เราต้องการทราบข้อเสนอแนะของนายเกี่ยวกับเกมนี้ ซึ่งนายจะได้รับรางวัลก้อนโตหลังจากทำแบบสำรวจเสร็จแล้ว!\n\nกติกาการเข้าร่วม:\n\n1. ตอบแบบสำรวจให้เสร็จสิ้นก่อน<color=#ffa200> 21-01-2021 00:00 ตามเวลา UTC</color> เพื่อรับ<color=#ffa200> ซีดี 200 แผ่น</color>\n2. คุณจะได้รับรางวัลก่อนวันที่<color=#ffa200> 27-01-2021 00:00 ตามเวลา UTC</color>\n3. ผู้เล่นแต่ละคนสามารถรับรางวัลได้เพียงครั้งเดียว\n4. คำตอบจากแบบสำรวจของนายใช้สำหรับการวิเคราะห์ภายในเท่านั้น\n\n[-1#Survey](herf=https://www.surveymonkey.com/r/TNW9665?user_id=%7Buser_id%7D)\n\nท่านรองโรเจอร์ | K12: Querido Capitán, \n\n¡Felicidades! Has sido seleccionado como uno de los monos suertudos para participar en nuestra encuesta. Para poder proporcionarte una mejor experiencia de juego, nos gustaría conocer tus sugerencias con relación al juego. ¡Tras de completar la encuesta, recibirás una gran recompensa! \n\nReglas de participación: \n\n1. Completa la encuesta antes del <color=#ffa200>21-01-2021 00:00 UTC</color> para recibir <color=#ffa200>200 CD</color>.\n2. La recompensa será emitida después del <color=#ffa200>27-1-2021 00:00 UTC</color>.\n3. Cada jugador solamente podrá obtener la recompensa una vez. \n4. Tus respuestas a la encuesta solamente son para análisis interno.\n\n[-1#Encuesta](herf=https://www.surveymonkey.com/r/TNW9665?user_id=%7Buser_id%7D)\n\nComisario Roger | L12: Уважаемый капитан!\n\nПоздравляем! Вам повезло попасть в число счастливчиков, отобранных для участия в опросе! Чтобы обеспечить вам наилучшие впечатления от игры, мы хотим выслушать ваши предложения. Когда вы пройдете опрос, то получите отличную награду!\n\nПравила участия:\n\n1. Пройдите опрос до <color=#ffa200>00:00 21.01.2021 (UTC)</color>, чтобы получить в награду <color=#ffa200>200 CD</color>.\n2. Награда будет выдана до <color=#ffa200>00:00 27.01.2021 (UTC)</color>.\n3. Каждый игрок может получить награду только один раз.\n4. Ваши ответы в опросе предназначены исключительно для внутреннего анализа.\n\n[-1#Survey](herf=https://www.surveymonkey.com/r/TNW9665?user_id=%7Buser_id%7D)\n\nПомощник Роджер | M12: Sevgili Kaptan,\n\nTebrikler! Anketimize katılacak şanslı maymunlardan biri olarak seçildin! Sana daha iyi bir oyun deneyimi sunabilmek için oyunla ilgili tavsiyelerini öğrenmek istiyoruz. Anketi tamamladıktan sonra harika bir ödül alacaksın!\n\nKatılım Kuralları:\n\n1. Anketi <color=#ffa200>21.01.2021, 00.00’dan (UTC)</color> önce tamamla ve <color=#ffa200>200 CD</color> kazan.\n2. Ödül <color=#ffa200>27.01.2021, 00.00’dan (UTC)</color> önce verilecek.\n3. Her oyuncu ödülü sadece bir kez alabilir.\n4. Anket cevapların sadece dâhilî analiz için kullanılacak.\n\n[-1#Anket]\n(herf=https://www.surveymonkey.com/r/TNW9665?user_id=%7Buser_id%7D)\n\nYardımcı Roger | N12: Thưa Thủ Lĩnh,\n\nXin chúc mừng! Bạn là một trong những chú khỉ may mắn được chọn để tham gia khảo sát của chúng tôi! Để có thể cung cấp một trải nghiệm trò chơi tốt hơn, chúng tôi muốn tìm hiểu các đề xuất của bạn về trò chơi. Sau khi hoàn thành khảo sát, bạn sẽ nhận được một phần thưởng thú vị!\n\nNội quy tham gia:\n\n1. Hoàn thành khảo sát trước <color=#ffa200>00:00 UTC ngày 21/01/2021</color> để nhận <color=#ffa200>200 CD</color>.\n2. Phần thưởng sẽ được phát trước <color=#ffa200>00:00 UTC ngày 27/01/2021</color>.\n3. Mỗi người chơi chỉ có thể nhận phần thưởng một lần duy nhất.\n4. Câu trả lời khảo sát của bạn chỉ được sử dụng để phân tích nội bộ.\n\n-1#Khảo sát](herf=https://www.surveymonkey.com/r/TNW9665?user_id=%7Buser_id%7D)\n\nPhụ tá Roger | O12: Caro Capitano,\n\nCongratulazioni! Sei stato selezionato tra le scimmie fortunate che potranno partecipare al nostro sondaggio! Per offrire una migliore esperienza di gioco, vorremmo conoscere i tuoi suggerimenti. Dopo aver completato il sondaggio, riceverai una grande ricompensa!\n\nRegole di partecipazione:\n\n1. Completa il sondaggio prima del <color=#ffa200>21/01/2022 00:00 UTC</color> per ricevere <color=#ffa200>200 CD</color>.\n2. La ricompensa verrà inviata prima del <color=#ffa200>27/01/2022 00>00 UTC</color>.\n3. Ogni giocatore può ottenere la ricompensa solo una volta.\n4. Le risposte del sondaggio sono solo per scopi di analisi interne.\n\n[-1#Survey](herf=https://www.surveymonkey.com/r/TNW9665?user_id=%7Buser_id%7D)\n\nSottotenente Roger | P12: Kapitanie,\n\nGratulacje! Jesteś jedną ze szczęśliwych małp wybranych do udziału w naszej ankiecie! Aby zapewnić lepsze wrażenia graczy, chcemy poznać Twoje sugestie dotyczące gry. Po wypełnieniu ankiety otrzymasz wspaniałą nagrodę!\n\nZasady udziału:\n\n1. Wypełnij ankietę do <color=#ffa200>21.01.2021, do godz. 00:00 (UTC)</color>, aby otrzymać <color=#ffa200>200 CD</color>.\n2. Nagroda zostanie przyznana do <color=#ffa200>27.01.2021, do godz. 00:00 (UTC)</color>.\n3. Każdy gracz może otrzymać nagrodę tylko raz.\n4. Odpowiedzi udzielone w ankiecie zostaną wykorzystane wyłącznie do wewnętrznej analizy.\n\n[-1#Survey](herf=https://www.surveymonkey.com/r/TNW9665?user_id=%7Buser_id%7D)\n\nZastępca Roger | Q12: عزيزي الزعيم،\n\n تهانينا! لقد تم اختيارك كواحد من الزعماء المحظوظين للمشاركة في الاستبيان الخاص بنا! من أجل تزويدك بتجربة لعب أفضل، نود أن نعرف اقتراحاتك حول اللعبة. بعد إكمال الاستبيان، ستحصل على مكافأة رائعة!\n\n قواعد المشاركة:\n\n1. أكمل الاستبيان قبل <color=#ffa200>2021-01-21 00:00 UTC</color> لتحصل على <color=#ffa200>200 قرص CD</color>. سيتم إصدار المكافأة قبل <color=#ffa200>2021-1-27 00:00 UTC</color>.\n3. يمكن لكل لاعب الحصول على المكافأة مرة واحدة فقط.\n4. إجابات الاستطلاع الخاصة بك هي للتحليل الداخلي فقط.\n\n[-1#استبيان](herf=https://www.surveymonkey.com/r/TNW9665?user_id=%7Buser_id%7D)\n\nالنائب روجر
B13: 问卷奖励 | C13: 问卷调查奖励 | D13: Survey Reward | E13: Récompense pour l'enquête | F13: Umfrage-Belohnung | G13: Recompensa de pesquisa | H13: 問卷調查獎勵 | I13: Hadiah Survei | J13: รางวัลของแบบสำรวจ | K13: Recompensa por la Encuesta | L13: Награда за опрос | M13: Anket Ödülü | N13: Quà khảo sát | O13: Ricompensa per il sondaggio | P13: Nagroda za ankietę | Q13: مكافآت الاستبيان
C14: 亲爱的指挥官：\n\n感谢您抽出宝贵的时间参与我们的问卷调查。您的反馈将帮助我们改善并为您带来更好的游戏体验。\n\n请收下您的奖励。期待和您在小酒馆喝一杯！\n\n罗杰副官 | D14: Dear Captain,\n\nThank you for taking to time to complete the survey. Your valuable feedback will help us improve and bring you a better gaming experience.\n\nPlease claim your survey reward. See you around the Tavern!\n\nDeputy Roger | E14: Cher capitaine,\n\nMerci d'avoir pris le temps de répondre à l'enquête. Vos précieux commentaires nous aideront à améliorer le jeu pour vous proposer une expérience optimale.\n\nVous pouvez récupérer votre récompense. A bientôt à la taverne!\n\nRoger l'assistant | F14: Lieber Captain,\n\nVielen Dank, dass du dir die Zeit genommen hast, die Umfrage auszufüllen. Dein wertvolles Feedback wird uns helfen, uns zu verbessern und dir ein besseres Spielerlebnis zu bieten.\n\nBitte fordere deine Belohnung ein. Wir sehen uns in der Taverne!\n\nAdjudant Roger | G14: Caro Capitão,\n\nAgradecemos por concluir a pesquisa. Seu feedback valioso nos ajudará a melhorar ainda mais a experiência de jogo para você.\n\nResgate sua recompensa pela pesquisa. Vemos você na taverna!\n\nDelegado Roger | H14: 親愛的指揮官：\n\n感謝您抽出寶貴的時間參與我們的問卷調查。您的反饋將幫助我們改善並為您帶來更好的遊戲體驗。\n\n請收下您的獎勵。期待和您在小酒館喝一杯！\n\n羅傑副官 | I14: Kapten yang terhormat,\n\nTerima kasih telah meluangkan waktu untuk menyelesaikan survei. Umpan balikmu yang berharga akan membantu kami meningkatkan dan memberikan pengalaman bermain game yang lebih baik.\n\nKlaim hadiah surveimu. Sampai jumpa di sekitar Kedai!\n\nDeputi Roger | J14: ถึงท่านผู้บัญชาการ\n\nขอขอบคุณที่สละเวลาทำแบบสำรวจ ความคิดเห็นที่มีค่าของนายจะช่วยให้เราปรับปรุงและนำเสนอประสบการณ์การเล่นเกมที่ดียิ่งขึ้นได้\n\nรีบไปรับรางวัลแบบสำรวจของนายสิ แล้วไว้เจอกันแถว ๆ โรงแรมนะ!\n\nท่านรองโรเจอร์ | K14: Querido Capitán, \n\nGracias por tomarte el tiempo para completar la encuesta. Tus valiosos comentarios nos ayudarán a mejorar y ofrecerte una mejor experiencia de juego. \n\nPor favor, reclama tu recompensa de la encuesta. ¡Nos vemos en la Taberna! \n\nComisario Roger | L14: Уважаемый капитан!\n\nСпасибо, что нашли время пройти наш опрос. Ваши ценные отзывы помогут нам совершенствоваться и дарить вам еще лучшие впечатления от игры.\n\nПожалуйста, заберите свою награду за участие. Увидимся в таверне!\n\nПомощник Роджер | M14: Sevgili Kaptan,\n\nZaman ayırıp anketimizi doldurduğun için teşekkürler. Değerli geri bildirimin gelişmemize ve sana daha iyi bir oyun deneyimi sunmamıza yardım edecek.\n\nLütfen anket ödülünü al. Tavernada görüşürüz!\n\nYardımcı Roger | N14: Thưa Thủ Lĩnh,\n\nCảm ơn bạn đã dành thời gian hoàn thành khảo sát. Phản hồi quý giá của bạn sẽ giúp chúng tôi cải thiện và cung cấp cho bạn trải nghiệm trò chơi tốt hơn.\n\nVui lòng nhận phần thưởng khảo sát của bạn. Hẹn gặp lại ở Tửu Quán nhé!\n\nPhụ tá Roger | O14: Caro Capitano,\n\nGrazie per aver dedicato del tempo al sondaggio. Il tuo prezioso feedback ci aiuterà a migliorare e offrire un'esperienza di gioco migliore.\n\nRiscatta la ricompensa per il sondaggio. Ci vediamo alla Taverna!\n\nSottotenente Roger | P14: Kapitanie,\n\nDziękujemy za czas poświęcony na wypełnienie ankiety. Twój wartościowy wkład pomoże nam poprawić wrażenia wszystkich graczy.\n\nOdbierz swoją nagrodę za ankietę. Do zobaczenia w Tawernie!\n\nZastępca Roger | Q14: عزيزي الزعيم،\n\n شكرًا لك على تخصيص بعض الوقت لإكمال الاستبيان. ستساعدنا ملاحظاتك القيّمة على التحسين وستجلب لك تجربة لعب أفضل.\n\n الرجاء إكتساب مكافأة الاستبيان. أراك حول المقهى!\n\n النائب روجر
A15: 故障问题 | B15: 问题已解决 | C15: 问题修复说明 | D15: Issue Fixed | E15: Problème résolu | F15: Problem behoben | G15: Problemas resolvidos | H15: 問題修復說明 | I15: Perbaikan Masalah | J15: แก้ไขปัญหาแล้ว | K15: Problema Resuelto | L15: Проблема решена | M15: Sorun Düzeltildi | N15: Đã khắc phục sự cố
C16: 亲爱的指挥官：\n\n你好，目前我们已经紧急修复了电路，城市已经<color=#ffa200>恢复正常</color>。\n为您带来不便深感歉意，在此为您送上一份补偿，请注意查收。\n我们将不断改进，希望能得到你的理解与支持，祝愿火箭发射顺利！\n\n罗杰副官 | D16: Dear Captain,\n\nOur team has successfully fixed the circuits and your City has <color=#ffa200>returned to normal</color>.\n\nWe apologize for the inconvenience and have included a small gift for you as compensation.\n\nThank you for your understanding and support as we continue to improve. See you around the Tavern!\n\nDeputy Roger | E16: Cher capitaine,\n\nNotre équipe a réussi à réparer les circuits et la situation est de <color=#ffa200>retour à la normale</color>.\n\nNous vous prions de nous excuser pour ce désagrément et vous offrons un petit cadeau en dédommagement.\n\nMerci pour votre compréhension et votre soutien. A bientôt à la taverne!\n\nRoger l'assistant | F16: Lieber Captain,\n\nUnser Team hat die Schaltkreise erfolgreich repariert und deine Stadt ist <color=#ffa200>zur Normalität zurückgekehrt</color>.\n\nWir entschuldigen uns für die Unannehmlichkeiten und haben als Entschädigung ein kleines Geschenk für dich beigefügt.\n\nVielen Dank für dein Verständnis und deine Unterstützung, während wir uns weiter verbessern. Wir sehen uns in der Taverne!\n\nAdjudant Roger | G16: Caro Capitão,\n\nNossa equipe foi bem-sucedida em consertar os circuitos e sua cidade <color=#ffa200>já voltou ao normal</color>.\n\nLamentamos pelo inconveniente e, por isso, incluímos um pequeno presente para você como compensação.\n\nNossa equipe agradece sua compreensão e apoio ao passo que continuamos melhorando. Vemos você na taverna!\n\nDelegado Roger | H16: 親愛的指揮官：\n\n你好，目前我們已經緊急修復了電路，城市已經<color=#ffa200>恢復正常</color>。\n為您帶來不便深感歉意，在此為您送上一份補償，請注意查收。\n我們將不斷改進，希望能得到你的理解與支持，祝愿火箭發射順利！\n\n羅傑副官 | I16: Kapten yang terhormat,\n\nTim kami berhasil memperbaiki sirkuit dan Kotamu telah <color=#ffa200>kembali normal</color>.\n\nKami mohon maaf atas ketidaknyamanannya dan telah menyertakan hadiah kecil untukmu sebagai kompensasi.\n\nTerima kasih atas pengertian dan dukunganmu sementara kami terus meningkatkan game. Sampai jumpa di sekitar Kedai!\n\nDeputi Roger | J16: ถึงท่านผู้บัญชาการ\n\nทีมของเราได้แก้ไขวงจรเรียบร้อยแล้ว และเมืองของนายก็<color=#ffa200>กลับสู่สภาวะปกติแล้ว</color>\n\nขออภัยในความไม่สะดวก เราจึงขอมอบของขวัญเล็ก ๆ น้อย ๆ นี้ให้เป็นการชดเชย\n\nขอขอบคุณสำหรับความเข้าใจและการสนับสนุนการปรับปรุงอย่างต่อเนื่องของเรา แล้วไว้เจอกันแถว ๆ โรงแรมนะ!\n\nท่านรองโรเจอร์ | K16: Querido Capitán, \n\nNuestro equipo ha corregido exitosamente los circuitos y tu Ciudad ha <color=#ffa200>regresado a la normalidad</color>.\n\nNos disculpamos por el inconveniente y hemos incluido un pequeño regalo para ti como compensación. \n\nGracias por tu comprensión y apoyo mientras continuamos mejorando. ¡Nos vemos en la Taberna!\n\nComisario Roger | L16: Уважаемый капитан!\n\nНаша команда успешно починила все микросхемы, и ваш город <color=#ffa200>вернулся к нормальной жизни</color>.\n\nПриносим извинения за неудобства и отправляем вам небольшой подарок в качестве компенсации!\n\nСпасибо за понимание и поддержку наших мер по улучшению игры. Увидимся в таверне!\n\nПомощник Роджер | M16: Sevgili Kaptan,\n\nEkibimiz devreleri başarıyla onardı ve Şehrin <color=#ffa200>normale döndü</color>.\n\nVerdiğimiz sıkıntıdan ötürü özür dileriz, bunun telafisi olarak sana küçük bir hediye sunuyoruz.\n\nGelişme sürecimizdeki anlayışın ve desteğin için teşekkürler. Tavernada görüşürüz!\n\nYardımcı Roger | N16: Thưa Thủ Lĩnh,\n\nĐội ngũ của chúng tôi đã sửa mạch điện thành công và Thành phố của bạn đã <color=#ffa200>trở lại bình thường</color>.\n\nChúng tôi xin lỗi vì sự bất tiện này và xin phép được tặng một món quà nhỏ để bù đắp cho bạn.\n\nCảm ơn các bạn đã thông cảm và ủng hộ trong thời gian chúng tôi tiếp tục cải thiện trò chơi. Hẹn gặp lại ở Tửu Quán nhé!\n\nPhụ tá Roger
B17: 数据异常 | C17: 紧急问题说明 | D17: Urgent Fix Ongoing | E17: Résolution urgente en cours | F17: Dringende Fehlerbehebung im Gange | G17: Ajuste urgente em andamento | H17: 緊急問題說明 | I17: Perbaikan Mendesak Sedang Berlangsung | J17: กำลังดำเนินการแก้ไขอย่างเร่งด่วน | K17: Arreglo urgente en curso | L17: Срочное исправление | M17: Acil Tamir Devam Ediyor | N17: Chúng tôi đang khẩn trương sửa lỗi
C18: 亲爱的指挥官：\n\n由于城市电路故障，你的城市可能会出现<color=#ffa200>数据异常</color>等情况，我们<color=#ffa200>正在紧急修复</color>电路。\n为您带来不便深感歉意，在此为您送上一份补偿，请注意查收。\n感谢您对Age of Apes的理解与支持，祝愿火箭发射顺利！\n\n罗杰副官 | D18: Dear Captain,\n\nDue to circuit malfunctions, your City may experience <color=#ffa200>data errors</color> or other issues. We are working hard to <color=#ffa200>fix these issues as quickly as possible</color>.\n\nWe apologize for the inconvenience and have included a small gift for you as compensation.\n\nThank you for your understanding and support. See you around the Tavern!\n\nDeputy Roger | E18: Cher capitaine,\n\nEn raison du dysfonctionnement d'un circuit, votre ville peut présenter des <color=#ffa200>erreurs de données</color> ou d'autres soucis. Nous travaillons dur pour <color=#ffa200>résoudre ces problèmes aussi vite que possible</color>.\n\nNous vous prions de nous excuser pour ce désagrément et vous offrons un petit cadeau en dédommagement.\n\nMerci pour votre compréhension et votre soutien. A bientôt à la taverne!\n\nRoger l'assistant | F18: Lieber Captain,\n\nAufgrund von Schaltkreisfehlern kann es in deiner Stadt zu <color=#ffa200>Datenfehlern</color> oder anderen Problemen kommen. Wir arbeiten hart daran, <color=#ffa200>diese Probleme so schnell wie möglich zu beheben</color>.\n\nWir entschuldigen uns für die Unannehmlichkeiten und haben als Entschädigung ein kleines Geschenk für dich beigefügt.\n\nVielen Dank für dein Verständnis und deine Unterstützung. Wir sehen uns in der Taverne!\n\nAdjudant Roger | G18: Caro Capitão,\n\nDevido a um mal funcionamento dos circuitos, sua cidade talvez enfrente<color=#ffa200> erros nos dados</color> ou outros problemas. Estamos trabalhando muito para <color=#ffa200>resolver esses problemas o quanto antes</color>.\n\nLamentamos pelo inconveniente e, por isso, incluímos um pequeno presente para você como compensação.\n\nNossa equipe agradece seu apoio e compreensão. Vemos você na taverna!\n\nDelegado Roger | H18: 親愛的指揮官：\n\n由於城市電路故障，你的城市可能會出現<color=#ffa200>數據異常</color>等情況，我們<color=#ffa200>正在緊急修復</color>電路。\n為您帶來不便深感歉意，在此為您送上一份補償，請注意查收。\n感謝你對Age of Apes的理解與支持，祝愿火箭發射順利！\n\n羅傑副官 | I18: Kapten yang terhormat,\n\nSehubungan dengan kerusakan sirkuit, Kotamu mungkin mengalami <color=#ffa200>kesalahan data</color> atau masalah lain. Kami bekerja keras untuk <color=#ffa200>memperbaiki masalah ini secepat mungkin</color>.\n\nKami mohon maaf atas ketidaknyamanannya dan telah menyertakan hadiah kecil untukmu sebagai kompensasi.\n\nTerima kasih atas pengertian dan dukunganmu. Sampai Jumpa di Sekitar Kedai!\n\nDeputi Roger | J18: ถึงท่านผู้บัญชาการ\n\nเนื่องจากวงจรทำงานผิดปกติ เมืองของนายอาจประสบ<color=#ffa200>การผิดพลาดเกี่ยวกับข้อมูล</color>หรือปัญหาอื่น ๆ ซึ่งเรากำลังดำเนินการอย่างเต็มที่เพื่อ<color=#ffa200>แก้ไขปัญหาเหล่านี้โดยเร็วที่สุด</color>\n\nขออภัยในความไม่สะดวก เราจึงขอมอบของขวัญเล็ก ๆ น้อย ๆ นี้ให้เป็นการชดเชย\n\nขอขอบคุณสำหรับความเข้าใจและการสนับสนุนของนาย แล้วไว้เจอกันแถว ๆ โรงแรมนะ!\n\nท่านรองโรเจอร์ | K18: Querido Capitán, \n\nDebido a unos fallos en los circuitos tu Ciudad puede experimentar <color=#ffa200>errores de datos</color> u otros problemas. Estamos trabajando duro para <color=#ffa200>corregir estos problemas tan pronto como sea posible</color>.\n\nNos disculpamos por el inconveniente y hemos incluido un pequeño regalo para ti como compensación. \n\nGracias por tu comprensión y apoyo. ¡Nos vemos en la Taberna!\n\nComisario Roger | L18: Уважаемый капитан!\n\nИз-за сбоев в работе микросхем в вашем городе могут возникнуть <color=#ffa200>ошибки данных</color> или другие проблемы. Мы прилагаем все усилия, чтобы <color=#ffa200>исправить эти неполадки как можно скорее</color>.\n\nПриносим извинения за неудобства и отправляем вам небольшой подарок в качестве компенсации!\n\nСпасибо за понимание и поддержку. Увидимся в таверне!\n\nПомощник Роджер | M18: Sevgili Kaptan,\n\nDevre bozuklukları nedeniyle Şehrin <color=#ffa200>veri hataları</color> veya başka sorunlar yaşayabilir. <color=#ffa200>Bu sorunları olabildiğince hızlı çözmek</color> için çalışıyoruz.\n\nVerdiğimiz sıkıntıdan ötürü özür dileriz, bunun telafisi olarak sana küçük bir hediye sunuyoruz.\n\nAnlayışın ve desteğin için teşekkürler. Tavernada görüşürüz!\n\nYardımcı Roger | N18: Thưa Thủ Lĩnh,\n\nDo sự cố trục trặc về mạch điện, Thành phố của bạn có thể gặp <color=#ffa200>lỗi dữ liệu</color> hoặc các vấn đề khác. Chúng tôi đang hết sức nỗ lực để <color=#ffa200>khắc phục sự cố sớm nhất có thể</color>.\n\nChúng tôi xin lỗi vì sự bất tiện này và xin phép được tặng một món quà nhỏ để bù đắp cho bạn.\n\nCảm ơn bạn đã thông cảm và hỗ trợ. Hẹn gặp lại ở Tửu Quán nhé!\n\nPhụ tá Roger
B19: 游戏卡顿 | C19: 紧急问题说明 | D19: Urgent Fix Ongoing | E19: Résolution urgente en cours | F19: Dringende Fehlerbehebung im Gange | G19: Ajuste urgente em andamento | H19: 緊急問題說明 | I19: Perbaikan Mendesak Sedang Berlangsung | J19: กำลังดำเนินการแก้ไขอย่างเร่งด่วน | K19: Arreglo urgente en curso | L19: Срочное исправление | M19: Acil Tamir Devam Ediyor | N19: Chúng tôi đang khẩn trương sửa lỗi
C20: 亲爱的指挥官：\n\n由于城市电路故障，你的城市可能会出现<color=#ffa200>游戏卡顿</color>等情况，我们<color=#ffa200>正在紧急修复</color>电路。\n为您带来不便深感歉意，在此为您送上一份补偿，请注意查收。\n感谢您对Age of Apes的理解与支持，祝愿火箭发射顺利！\n\n罗杰副官 | D20: Dear Captain,\n\nDue to circuit malfunctions, your City may experience <color=#ffa200>freezes</color> or other issues. We are working hard to <color=#ffa200>fix these issues as quickly as possible</color>.\n\nWe apologize for the inconvenience and have included a small gift for you as compensation.\n\nThank you for your understanding and support. See you around the Tavern!\n\nDeputy Roger | E20: Cher capitaine,\n\nEn raison du dysfonctionnement d'un circuit, votre ville peut se <color=#ffa200>figer</color> ou présenter d'autres soucis. Nous travaillons dur pour <color=#ffa200>résoudre ces problèmes aussi vite que possible</color>.\n\nNous vous prions de nous excuser pour ce désagrément et vous offrons un petit cadeau en dédommagement.\n\nMerci pour votre compréhension et votre soutien. A bientôt à la taverne!\n\nRoger l'assistant | F20: Lieber Captain,\n\nAufgrund von Schaltkreisfehlern kann es in deiner Stadt zu <color=#ffa200>Programmabstürzen</color> oder anderen Problemen kommen. Wir arbeiten hart daran, <color=#ffa200>diese Probleme so schnell wie möglich zu beheben</color>.\n\nWir entschuldigen uns für die Unannehmlichkeiten und haben als Entschädigung ein kleines Geschenk für dich beigefügt.\n\nVielen Dank für dein Verständnis und deine Unterstützung. Wir sehen uns in der Taverne!\n\nAdjudant Roger" | G20: Caro Capitão,\n\nDevido a um mal funcionamento dos circuitos, sua cidade talvez enfrente <color=#ffa200>travamentos</color> ou outros problemas. Estamos trabalhando muito para <color=#ffa200>resolver esses problemas o quanto antes</color>.\n\nLamentamos pelo inconveniente e, por isso, incluímos um pequeno presente para você como compensação.\n\nNossa equipe agradece seu apoio e compreensão. Vemos você na taverna!\n\nDelegado Roger | H20: 親愛的指揮官：\n\n由於城市電路故障，你的城市可能會出現<color=#ffa200>遊戲卡頓</color>等情況，我們<color=#ffa200>正在緊急修復</color>電路。\n為您帶來不便深感歉意，在此為您送上一份補償，請注意查收。\n感謝你對Age of Apes的理解與支持，祝愿火箭發射順利！\n\n羅傑副官 | I20: Kapten yang terhormat,\n\nSehubungan dengan kerusakan sirkuit, Kotamu mungkin mengalami <color=#ffa200>freezes</color> atau masalah lain. Kami bekerja keras untuk <color=#ffa200>memperbaiki masalah ini secepat mungkin</color>.\n\nKami mohon maaf atas ketidaknyamanannya dan telah menyertakan hadiah kecil untukmu sebagai kompensasi.\n\nTerima kasih atas pengertian dan dukunganmu. Sampai Jumpa di Sekitar Kedai!\n\nDeputi Roger | J20: ถึงท่านผู้บัญชาการ\n\nเนื่องจากวงจรทำงานผิดปกติ เมืองของนายอาจประสบปัญหา<color=#ffa200>อาการค้าง</color>หรือปัญหาอื่น ๆ ได้ ซึ่งเรากำลังดำเนินการอย่างเต็มที่เพื่อ<color=#ffa200>แก้ไขปัญหาเหล่านี้โดยเร็วที่สุด</color>\n\nขออภัยในความไม่สะดวก เราจึงขอมอบของขวัญเล็ก ๆ น้อย ๆ นี้ให้เป็นการชดเชย\n\nขอขอบคุณสำหรับความเข้าใจและการสนับสนุนของนาย แล้วไว้เจอกันแถว ๆ โรงแรมนะ!\n\nท่านรองโรเจอร์ | K20: Querido Capitán, \n\nDebido a unos fallos en los circuitos tu Ciudad puede experimentar <color=#ffa200>bloqueos</color> u otros problemas. Estamos trabajando duro para <color=#ffa200>corregir estos problemas tan pronto como sea posible</color>.\n\nNos disculpamos por el inconveniente y hemos incluido un pequeño regalo para ti como compensación. \n\nGracias por tu comprensión y apoyo. ¡Nos vemos en la Taberna!\n\nComisario Roger | L20: Уважаемый капитан!\n\nИз-за сбоев в работе микросхем в вашем городе могут возникнуть <color=#ffa200>зависания</color> или другие проблемы. Мы прилагаем все усилия, чтобы <color=#ffa200>исправить эти неполадки как можно скорее</color>.\n\nПриносим извинения за неудобства и отправляем вам небольшой подарок в качестве компенсации!\n\nСпасибо за понимание и поддержку. Увидимся в таверне!\n\nПомощник Роджер | M20: Sevgili Kaptan,\n\nDevre bozuklukları nedeniyle Şehrin <color=#ffa200>donmalar</color> veya başka sorunlar yaşayabilir. <color=#ffa200>Bu sorunları olabildiğince hızlı çözmek</color> için çalışıyoruz.\n\nVerdiğimiz sıkıntıdan ötürü özür dileriz, bunun telafisi olarak sana küçük bir hediye sunuyoruz.\n\nAnlayışın ve desteğin için teşekkürler. Tavernada görüşürüz!\n\nYardımcı Roger | N20: Thưa Thủ Lĩnh,\n\nDo sự cố trục trặc về mạch điện, Thành phố của bạn có thể gặp <color=#ffa200>lỗi ngưng vận hành</color> hoặc các vấn đề khác. Chúng tôi đang hết sức nỗ lực để <color=#ffa200>khắc phục sự cố sớm nhất có thể</color>.\n\nChúng tôi xin lỗi vì sự bất tiện này và xin phép được tặng một món quà nhỏ để bù đắp cho bạn.\n\nCảm ơn bạn đã thông cảm và hỗ trợ. Hẹn gặp lại ở Tửu Quán nhé!\n\nPhụ tá Roger
B21: 部队丢失 | C21: 部队异常说明 | D21: Troop Data Error | E21: Erreur de données liées aux troupes | F21: Truppendatenfehler | G21: Erro nos dados de tropas | H21: 部隊異常說明 | I21: Kesalahan Data Pasukan | J21: ข้อผิดพลาดเกี่ยวกับข้อมูลกองทหาร | K21: Error en los Datos de la Tropa | L21: Ошибка данных войск | M21: Birlik Verisi Hatası | N21: Lỗi dữ liệu binh lính
C22: 亲爱的指挥官：\n\n你好，由于城市电路发生故障，你的部队可能会出现<color=#ffa200>丢失</color>的情况。我们正在处理解决这个问题。\n为您带来不便深感歉意，在此为您送上一份补偿，请注意查收。\n我们将不断改进，希望能得到你的理解与支持，祝愿火箭发射顺利！\n\n罗杰副官 | D22: Dear Captain,\n\nDue to circuit malfunctions, you may experience problems with <color=#ffa200>missing troops</color>. We are currently working to fix this issue.\n\nWe apologize for the inconvenience and have included a small gift for you as compensation.\n\nThank you for your understanding and support as we continue to improve. See you around the Tavern!\n\nDeputy Roger | E22: Cher capitaine,\n\nEn raison du dysfonctionnement d'un circuit, vous avez peut-être constaté des <color=#ffa200>troupes manquantes</color>. Nous travaillons actuellement à résoudre ce souci.\n\nNous vous prions de nous excuser pour ce désagrément et vous offrons un petit cadeau en dédommagement.\n\nMerci pour votre compréhension et votre soutien. A bientôt à la taverne!\n\nRoger l'assistant | F22: Lieber Captain,\n\nAufgrund von Schaltkreisfehlern kann es bei dir zu Problemen mit <color=#ffa200>fehlenden Truppen</color> kommen. Wir arbeiten aktuell daran, dieses Problem zu beheben.\n\nWir entschuldigen uns für die Unannehmlichkeiten und haben als Entschädigung ein kleines Geschenk für dich beigefügt.\n\nVielen Dank für dein Verständnis und deine Unterstützung, während wir uns weiter verbessern. Wir sehen uns in der Taverne!\n\nAdjudant Roger | G22: Caro Capitão,\n\nDevido a um mal funcionamento dos circuitos, você talvez tenha problemas com <color=#ffa200>tropas perdidas</color>. Estamos trabalhando para resolver esse problema.\n\nLamentamos pelo inconveniente e, por isso, incluímos um pequeno presente para você como compensação.\n\nNossa equipe agradece sua compreensão e apoio ao passo que continuamos melhorando. Vemos você na taverna!\n\nDelegado Roger | H22: 親愛的指揮官：\n\n你好，由於城市電路發生故障，你的部隊可能會出現<color=#ffa200>丟失</color>的情況。我們正在處理解決這個問題。\n為您帶來不便深感歉意，在此為您送上一份補償，請注意查收。\n我們將不斷改進，希望能得到你的理解與支持，祝愿火箭發射順利！\n\n羅傑副官 | I22: Kapten yang terhormat,\n\nSehubungan dengan kerusakan sirkuit, kamu mungkin mengalami masalah dengan <color=#ffa200>pasukan yang hilang</color>. Kami sedang berusaha untuk memperbaiki masalah ini.\n\nKami mohon maaf atas ketidaknyamanannya dan telah menyertakan hadiah kecil untukmu sebagai kompensasi.\n\nTerima kasih atas pengertian dan dukunganmu sementara kami terus meningkatkan game. Sampai jumpa di sekitar Kedai!\n\nDeputi Roger | J22: ถึงท่านผู้บัญชาการ\n\nเนื่องจากวงจรทำงานผิดปกติ นายอาจประสบปัญหา<color=#ffa200>กองทหารสูญหาย</color> ซึ่งในขณะนี้ เรากำลังดำเนินการแก้ไขปัญหานี้อย่างเต็มที่\n\nขออภัยในความไม่สะดวก เราจึงขอมอบของขวัญเล็ก ๆ น้อย ๆ ให้เป็นการชดเชย\n\nขอขอบคุณสำหรับความเข้าใจและการสนับสนุนการปรับปรุงอย่างต่อเนื่องของเรา แล้วไว้เจอกันแถว ๆ โรงแรมนะ!\n\nท่านรองโรเจอร์ | K22: Querido Capitán, \n\nDebido a unos fallos en los circuitos, puedes experimentar problemas con <color=#ffa200>tropas faltantes</color>. Estamos trabajando en este momento para corregir este problema.\n\nNos disculpamos por el inconveniente y hemos incluido un pequeño regalo para ti como compensación. \n\nGracias por tu comprensión y apoyo mientras continuamos mejorando. ¡Nos vemos en la Taberna!\n\nComisario Roger | L22: Уважаемый капитан!\n\nИз-за сбоев в работе микросхем в вашем городе могут возникнуть проблемы с <color=#ffa200>исчезновением войск</color>. Мы прилагаем все усилия, чтобы исправить эти неполадки.\n\nПриносим извинения за неудобства и отправляем вам небольшой подарок в качестве компенсации!\n\nСпасибо за понимание и поддержку наших мер по улучшению игры. Увидимся в таверне!\n\nПомощник Роджер | M22: Sevgili Kaptan,\n\nDevre bozuklukları nedeniyle <color=#ffa200>eksik birlikler</color> konusunda sorun yaşayabilirsin. Bu sorunu çözmek için şu anda çalışıyoruz.\n\nVerdiğimiz sıkıntıdan ötürü özür dileriz, bunun telafisi olarak sana küçük bir hediye sunuyoruz.\n\nGelişme sürecimizdeki anlayışın ve desteğin için teşekkürler. Tavernada görüşürüz!\n\nYardımcı Roger | N22: Thưa Thủ Lĩnh,\n\nDo sự cố trục trặc về mạch điện, bạn có thể gặp tình trạng <color=#ffa200>binh lính mất tích</color>. Chúng tôi hiện đang tìm cách khắc phục sự cố này.\n\nChúng tôi xin lỗi vì sự bất tiện này và xin phép được tặng một món quà nhỏ để bù đắp cho bạn.\n\nCảm ơn bạn đã thông cảm và ủng hộ trong thời gian chúng tôi tiếp tục cải thiện trò chơi. Hẹn gặp lại ở Tửu Quán nhé!\n\nPhụ tá Roger
B23: 部队丢失修复 | C23: 部队异常修复说明 | D23: Troop Data Error Fixed | E23: Résolution de l'erreur de données liées aux troupes | F23: Truppendatenfehler behoben | G23: Erro nos dados de tropas resolvido | H23: 部隊異常修復說明 | I23: Kesalahan Data Pasukan Diperbaiki | J23: แก้ไขข้อผิดพลาดเกี่ยวกับข้อมูลกองทหารแล้ว | K23: Error en los Datos de la Tropa corregido | L23: Ошибка данных войск исправлена | M23: Birlik Verisi Hatası Düzeltildi | N23: Đã khắc phục lỗi dữ liệu binh lính
